{	
	"registryname": "assembly_stand_mk3",
    "localizedname": "装配台MK3",
    "color":"000000",
    "parts": [
        {
            "x": -1,
            "y": 0,
            "z": 0,
            "elements": [
                "extrabotany:blockorichalcos@0"
            ]
        },
        {
            "x": -3,
            "y": -2,
            "z": -1,
            "elements": [
                "chisel:lavastone1@0"
            ]
        },
        {
            "x": -2,
            "y": 0,
            "z": 0,
            "elements": [
                "extrabotany:blockorichalcos@0"
            ]
        },
        {
            "x": 1,
            "y": 0,
            "z": 0,
            "elements": [
                "extrabotany:blockorichalcos@0"
            ]
        },
        {
            "x": 2,
            "y": 0,
            "z": 0,
            "elements": [
                "extrabotany:blockorichalcos@0"
            ]
        },
        {
            "x": -3,
            "y": -2,
            "z": 3,
            "elements": [
                "chisel:lavastone1@0"
            ]
        },
        {
            "x": -2,
            "y": -2,
            "z": 3,
            "elements": [
                "chisel:lavastone1@0"
            ]
        },
        {
            "x": -1,
            "y": -2,
            "z": 3,
            "elements": [
                "chisel:lavastone1@0"
            ]
        },
        {
            "x": 0,
            "y": -2,
            "z": 3,
            "elements": [
                "chisel:lavastone1@0"
            ]
        },
        {
            "x": 1,
            "y": -2,
            "z": 3,
            "elements": [
                "chisel:lavastone1@0"
            ]
        },
        {
            "x": 2,
            "y": -2,
            "z": 3,
            "elements": [
                "chisel:lavastone1@0"
            ]
        },
        {
            "x": 3,
            "y": -2,
            "z": 3,
            "elements": [
                "chisel:lavastone1@0"
            ]
        },
        {
            "x": 4,
            "y": -7,
            "z": -3,
            "elements": [
                "bloodmagic:blood_rune@5"
            ]
        },
        {
            "x": 3,
            "y": -7,
            "z": -3,
            "elements": [
                "modularmachinery:blockinputbus@6"
            ]
        },
        {
            "x": 2,
            "y": -7,
            "z": -3,
            "elements": [
                "bloodmagic:blood_rune@5"
            ]
        },
        {
            "x": 3,
            "y": -1,
            "z": 0,
            "elements": [
                "extrabotany:blockorichalcos@0"
            ]
        },
        {
            "x": 2,
            "y": -1,
            "z": 0,
            "elements": [
                "extrabotany:blockorichalcos@0"
            ]
        },
        {
            "x": -2,
            "y": -7,
            "z": -3,
            "elements": [
                "bloodmagic:blood_rune@7"
            ]
        },
        {
            "x": -3,
            "y": -7,
            "z": -3,
            "elements": [
                "modularmachinery:blockfluidinputhatch@7"
            ]
        },
        {
            "x": 0,
            "y": 1,
            "z": 0,
            "elements": [
                "extrautils2:compressedcobblestone@7"
            ]
        },
        {
            "x": -4,
            "y": -7,
            "z": -3,
            "elements": [
                "bloodmagic:blood_rune@7"
            ]
        },
        {
            "x": 3,
            "y": 1,
            "z": -3,
            "elements": [
                "botania:pylon@2"
            ]
        },
        {
            "x": -2,
            "y": -1,
            "z": 0,
            "elements": [
                "extrabotany:blockorichalcos@0"
            ]
        },
        {
            "x": -3,
            "y": -1,
            "z": 0,
            "elements": [
                "extrabotany:blockorichalcos@0"
            ]
        },
        {
            "x": -3,
            "y": -1,
            "z": 3,
            "elements": [
                "chisel:waterstone1@0"
            ]
        },
        {
            "x": 0,
            "y": -1,
            "z": 3,
            "elements": [
                "extrabotany:blockorichalcos@0"
            ]
        },
        {
            "x": -1,
            "y": -5,
            "z": 1,
            "elements": [
                "appliedenergistics2:molecular_assembler@0"
            ]
        },
        {
            "x": -3,
            "y": 1,
            "z": -3,
            "elements": [
                "botania:pylon@2"
            ]
        },
        {
            "x": 0,
            "y": -5,
            "z": 1,
            "elements": [
                "appliedenergistics2:molecular_assembler@0"
            ]
        },
        {
            "x": 3,
            "y": -1,
            "z": 3,
            "elements": [
                "chisel:waterstone1@0"
            ]
        },
        {
            "x": 1,
            "y": -5,
            "z": 1,
            "elements": [
                "appliedenergistics2:molecular_assembler@0"
            ]
        },
        {
            "x": -3,
            "y": -7,
            "z": 4,
            "elements": [
                "bloodmagic:blood_rune@7"
            ]
        },
        {
            "x": 3,
            "y": -7,
            "z": 4,
            "elements": [
                "bloodmagic:blood_rune@10"
            ]
        },
        {
            "x": 5,
            "y": -8,
            "z": -3,
            "elements": [
                "bloodmagic:blood_rune@5"
            ]
        },
        {
            "x": 1,
            "y": -8,
            "z": -3,
            "elements": [
                "bloodmagic:blood_rune@5"
            ]
        },
        {
            "x": 3,
            "y": -2,
            "z": 0,
            "elements": [
                "chisel:lavastone1@0"
            ]
        },
        {
            "x": 1,
            "y": -4,
            "z": -1,
            "elements": [
                "appliedenergistics2:crafting_storage_64k@2"
            ]
        },
        {
            "x": -1,
            "y": -8,
            "z": -3,
            "elements": [
                "bloodmagic:blood_rune@7"
            ]
        },
        {
            "x": 0,
            "y": -4,
            "z": -1,
            "elements": [
                "tp:octuple_compressed_nether_block@0"
            ]
        },
        {
            "x": -1,
            "y": -4,
            "z": -1,
            "elements": [
                "appliedenergistics2:crafting_storage_64k@2"
            ]
        },
        {
            "x": 0,
            "y": -2,
            "z": 0,
            "elements": [
                "minecraft:dragon_egg@0"
            ]
        },
        {
            "x": 3,
            "y": 0,
            "z": -3,
            "elements": [
                "chisel:waterstone1@0"
            ]
        },
        {
            "x": -5,
            "y": -8,
            "z": -3,
            "elements": [
                "bloodmagic:blood_rune@7"
            ]
        },
        {
            "x": -3,
            "y": 0,
            "z": 3,
            "elements": [
                "chisel:waterstone1@0"
            ]
        },
        {
            "x": -3,
            "y": -2,
            "z": 0,
            "elements": [
                "chisel:lavastone1@0"
            ]
        },
        {
            "x": -3,
            "y": -2,
            "z": 2,
            "elements": [
                "chisel:lavastone1@0"
            ]
        },
        {
            "x": -1,
            "y": -4,
            "z": 1,
            "elements": [
                "appliedenergistics2:crafting_storage_64k@2"
            ]
        },
        {
            "x": -3,
            "y": 0,
            "z": -3,
            "elements": [
                "chisel:waterstone1@0"
            ]
        },
        {
            "x": 0,
            "y": -4,
            "z": 1,
            "elements": [
                "tp:octuple_compressed_sugar_cane@0"
            ]
        },
        {
            "x": 3,
            "y": 0,
            "z": 3,
            "elements": [
                "chisel:waterstone1@0"
            ]
        },
        {
            "x": 1,
            "y": -4,
            "z": 1,
            "elements": [
                "appliedenergistics2:crafting_storage_64k@2"
            ]
        },
        {
            "x": -5,
            "y": -8,
            "z": 3,
            "elements": [
                "bloodmagic:blood_rune@7"
            ]
        },
        {
            "x": 3,
            "y": -2,
            "z": 2,
            "elements": [
                "chisel:lavastone1@0"
            ]
        },
        {
            "x": -1,
            "y": -8,
            "z": 3,
            "elements": [
                "bloodmagic:blood_rune@7"
            ]
        },
        {
            "x": 1,
            "y": -8,
            "z": 3,
            "elements": [
                "bloodmagic:blood_rune@10"
            ]
        },
        {
            "x": 5,
            "y": -8,
            "z": 3,
            "elements": [
                "bloodmagic:blood_rune@10"
            ]
        },
        {
            "x": 3,
            "y": -7,
            "z": -2,
            "elements": [
                "bloodmagic:blood_rune@5"
            ]
        },
        {
            "x": 1,
            "y": -5,
            "z": -1,
            "elements": [
                "appliedenergistics2:molecular_assembler@0"
            ]
        },
        {
            "x": 0,
            "y": -5,
            "z": -1,
            "elements": [
                "appliedenergistics2:molecular_assembler@0"
            ]
        },
        {
            "x": -1,
            "y": -5,
            "z": -1,
            "elements": [
                "appliedenergistics2:molecular_assembler@0"
            ]
        },
        {
            "x": 0,
            "y": -3,
            "z": 0,
            "elements": [
                "draconicevolution:draconic_block@0"
            ]
        },
        {
            "x": -3,
            "y": -7,
            "z": -2,
            "elements": [
                "bloodmagic:blood_rune@7"
            ]
        },
        {
            "x": 3,
            "y": -1,
            "z": -3,
            "elements": [
                "chisel:waterstone1@0"
            ]
        },
        {
            "x": -3,
            "y": 1,
            "z": 3,
            "elements": [
                "botania:pylon@2"
            ]
        },
        {
            "x": 0,
            "y": -1,
            "z": -3,
            "elements": [
                "extrabotany:blockorichalcos@0"
            ]
        },
        {
            "x": 0,
            "y": -1,
            "z": 2,
            "elements": [
                "extrabotany:blockorichalcos@0"
            ]
        },
        {
            "x": -3,
            "y": -1,
            "z": -3,
            "elements": [
                "chisel:waterstone1@0"
            ]
        },
        {
            "x": 3,
            "y": 1,
            "z": 3,
            "elements": [
                "botania:pylon@2"
            ]
        },
        {
            "x": -4,
            "y": -7,
            "z": 3,
            "elements": [
                "bloodmagic:blood_rune@7"
            ]
        },
        {
            "x": -3,
            "y": -7,
            "z": 3,
            "elements": [
                "modularmachinery:blockfluidinputhatch@7"
            ]
        },
        {
            "x": -2,
            "y": -7,
            "z": 3,
            "elements": [
                "bloodmagic:blood_rune@7"
            ]
        },
        {
            "x": 2,
            "y": -7,
            "z": 3,
            "elements": [
                "bloodmagic:blood_rune@10"
            ]
        },
        {
            "x": 3,
            "y": -7,
            "z": 3,
            "elements": [
                "modularmachinery:blockenergyinputhatch@7"
            ]
        },
        {
            "x": 4,
            "y": -7,
            "z": 3,
            "elements": [
                "bloodmagic:blood_rune@10"
            ]
        },
        {
            "x": 1,
            "y": -4,
            "z": 0,
            "elements": [
                "appliedenergistics2:crafting_storage_64k@2"
            ]
        },
        {
            "x": 0,
            "y": -4,
            "z": 0,
            "elements": [
                "appliedenergistics2:spatial_pylon@0"
            ]
        },
        {
            "x": -1,
            "y": -4,
            "z": 0,
            "elements": [
                "appliedenergistics2:crafting_storage_64k@2"
            ]
        },
        {
            "x": 3,
            "y": -2,
            "z": -3,
            "elements": [
                "chisel:lavastone1@0"
            ]
        },
        {
            "x": 2,
            "y": -2,
            "z": -3,
            "elements": [
                "chisel:lavastone1@0"
            ]
        },
        {
            "x": 1,
            "y": -2,
            "z": -3,
            "elements": [
                "chisel:lavastone1@0"
            ]
        },
        {
            "x": 0,
            "y": -2,
            "z": -3,
            "elements": [
                "chisel:lavastone1@0"
            ]
        },
        {
            "x": -3,
            "y": -2,
            "z": 1,
            "elements": [
                "chisel:lavastone1@0"
            ]
        },
        {
            "x": 0,
            "y": 0,
            "z": -2,
            "elements": [
                "extrabotany:blockorichalcos@0"
            ]
        },
        {
            "x": -1,
            "y": -2,
            "z": -3,
            "elements": [
                "chisel:lavastone1@0"
            ]
        },
        {
            "x": 0,
            "y": 0,
            "z": 2,
            "elements": [
                "extrabotany:blockorichalcos@0"
            ]
        },
        {
            "x": -2,
            "y": -2,
            "z": -3,
            "elements": [
                "chisel:lavastone1@0"
            ]
        },
        {
            "x": -3,
            "y": -2,
            "z": -3,
            "elements": [
                "chisel:lavastone1@0"
            ]
        },
        {
            "x": 3,
            "y": -2,
            "z": 1,
            "elements": [
                "chisel:lavastone1@0"
            ]
        },
        {
            "x": -3,
            "y": -6,
            "z": 3,
            "elements": [
                "chisel:tyrian@12"
            ]
        },
        {
            "x": 3,
            "y": -6,
            "z": 3,
            "elements": [
                "chisel:tyrian@12"
            ]
        },
        {
            "x": 1,
            "y": -5,
            "z": 0,
            "elements": [
                "appliedenergistics2:molecular_assembler@0"
            ]
        },
        {
            "x": 0,
            "y": -5,
            "z": 0,
            "elements": [
                "appliedenergistics2:interface@0"
            ]
        },
        {
            "x": -1,
            "y": -5,
            "z": 0,
            "elements": [
                "appliedenergistics2:molecular_assembler@0"
            ]
        },
        {
            "x": 3,
            "y": -3,
            "z": -3,
            "elements": [
                "chisel:waterstone1@0"
            ]
        },
        {
            "x": 0,
            "y": -1,
            "z": -2,
            "elements": [
                "extrabotany:blockorichalcos@0"
            ]
        },
        {
            "x": -3,
            "y": -3,
            "z": -3,
            "elements": [
                "chisel:waterstone1@0"
            ]
        },
        {
            "x": -3,
            "y": -5,
            "z": 3,
            "elements": [
                "chisel:waterstone1@0"
            ]
        },
        {
            "x": -3,
            "y": -7,
            "z": 2,
            "elements": [
                "bloodmagic:blood_rune@7"
            ]
        },
        {
            "x": 3,
            "y": -5,
            "z": 3,
            "elements": [
                "chisel:waterstone1@0"
            ]
        },
        {
            "x": 3,
            "y": -7,
            "z": 2,
            "elements": [
                "bloodmagic:blood_rune@10"
            ]
        },
        {
            "x": 3,
            "y": -8,
            "z": -1,
            "elements": [
                "bloodmagic:blood_rune@5"
            ]
        },
        {
            "x": 0,
            "y": -8,
            "z": -1,
            "elements": [
                "chisel:futura@4"
            ]
        },
        {
            "x": 3,
            "y": -8,
            "z": -5,
            "elements": [
                "bloodmagic:blood_rune@5"
            ]
        },
        {
            "x": 0,
            "y": -6,
            "z": 0,
            "elements": [
                "chisel:energizedvoidstone@6"
            ]
        },
        {
            "x": -3,
            "y": -8,
            "z": -1,
            "elements": [
                "bloodmagic:blood_rune@7"
            ]
        },
        {
            "x": 3,
            "y": -4,
            "z": -3,
            "elements": [
                "chisel:waterstone1@0"
            ]
        },
        {
            "x": 3,
            "y": -2,
            "z": -2,
            "elements": [
                "chisel:lavastone1@0"
            ]
        },
        {
            "x": -3,
            "y": -8,
            "z": -5,
            "elements": [
                "bloodmagic:blood_rune@7"
            ]
        },
        {
            "x": 0,
            "y": 0,
            "z": -1,
            "elements": [
                "extrabotany:blockorichalcos@0"
            ]
        },
        {
            "x": 0,
            "y": 0,
            "z": 1,
            "elements": [
                "extrabotany:blockorichalcos@0"
            ]
        },
        {
            "x": -3,
            "y": -4,
            "z": -3,
            "elements": [
                "chisel:waterstone1@0"
            ]
        },
        {
            "x": -3,
            "y": -2,
            "z": -2,
            "elements": [
                "chisel:lavastone1@0"
            ]
        },
        {
            "x": -3,
            "y": -4,
            "z": 3,
            "elements": [
                "chisel:waterstone1@0"
            ]
        },
        {
            "x": -3,
            "y": -8,
            "z": 1,
            "elements": [
                "bloodmagic:blood_rune@7"
            ]
        },
        {
            "x": 0,
            "y": -8,
            "z": 1,
            "elements": [
                "chisel:futura@4"
            ]
        },
        {
            "x": -3,
            "y": -8,
            "z": 5,
            "elements": [
                "bloodmagic:blood_rune@7"
            ]
        },
        {
            "x": 3,
            "y": -4,
            "z": 3,
            "elements": [
                "chisel:waterstone1@0"
            ]
        },
        {
            "x": 3,
            "y": -8,
            "z": 1,
            "elements": [
                "bloodmagic:blood_rune@10"
            ]
        },
        {
            "x": 3,
            "y": -8,
            "z": 5,
            "elements": [
                "bloodmagic:blood_rune@10"
            ]
        },
        {
            "x": 0,
            "y": -7,
            "z": 0,
            "elements": [
                "modularmachinery:blockoutputbus@6"
            ]
        },
        {
            "x": 3,
            "y": -7,
            "z": -4,
            "elements": [
                "bloodmagic:blood_rune@5"
            ]
        },
        {
            "x": 3,
            "y": -5,
            "z": -3,
            "elements": [
                "chisel:waterstone1@0"
            ]
        },
        {
            "x": -3,
            "y": -7,
            "z": -4,
            "elements": [
                "bloodmagic:blood_rune@7"
            ]
        },
        {
            "x": -3,
            "y": -5,
            "z": -3,
            "elements": [
                "chisel:waterstone1@0"
            ]
        },
        {
            "x": -3,
            "y": -3,
            "z": 3,
            "elements": [
                "chisel:waterstone1@0"
            ]
        },
        {
            "x": 3,
            "y": -3,
            "z": 3,
            "elements": [
                "chisel:waterstone1@0"
            ]
        },
        {
            "x": 1,
            "y": -8,
            "z": 0,
            "elements": [
                "chisel:futura@4"
            ]
        },
        {
            "x": 0,
            "y": -8,
            "z": 0,
            "elements": [
                "avaritia:extreme_crafting_table@0"
            ]
        },
        {
            "x": -1,
            "y": -8,
            "z": 0,
            "elements": [
                "chisel:futura@4"
            ]
        },
        {
            "x": 3,
            "y": -6,
            "z": -3,
            "elements": [
                "chisel:tyrian@12"
            ]
        },
        {
            "x": 3,
            "y": -2,
            "z": -1,
            "elements": [
                "chisel:lavastone1@0"
            ]
        },
        {
            "x": -3,
            "y": -6,
            "z": -3,
            "elements": [
                "chisel:tyrian@12"
            ]
        }
    ]}